<?xml version="1.0" ?>
<!-- =================================================================================== -->
<!-- |    This document was autogenerated by xacro from collector_bot.xacro            | -->
<!-- |    EDITING THIS FILE BY HAND IS NOT RECOMMENDED                                 | -->
<!-- =================================================================================== -->
<robot name="collector_bot" xmlns:xacro="http://www.ros.org/wiki/xacro">
  <!-- Properties (all values in meters) -->
  <!-- Links -->
  <link name="base_link">
    <collision name="collision">
      <origin xyz="0 0 .1"/>
      <geometry>
        <box size="0.6096 0.4572 0.1"/>
      </geometry>
    </collision>
    <visual name="visual">
      <origin xyz="0 0 .1"/>
      <geometry>
        <box size="0.6096 0.4572 0.1"/>
      </geometry>
      <material name="tan">
        <color rgba=".8 0.7 .55 1"/>
      </material>
    </visual>
  </link>
  <link name="caster">
    <collision name="collision">
      <geometry>
        <sphere radius="0.03175"/>
      </geometry>
    </collision>
    <visual name="visual">
      <geometry>
        <sphere radius="0.03175"/>
      </geometry>
      <material name="dark_grey">
        <color rgba=".3 .3 .3 1"/>
      </material>
    </visual>
  </link>
  <link name="left_wheel_link">
    <collision>
      <geometry>
        <cylinder length="0.05" radius="0.0619125"/>
      </geometry>
    </collision>
    <visual>
      <geometry>
        <cylinder length="0.05" radius="0.0619125"/>
      </geometry>
      <material name="dark_grey">
        <color rgba=".3 .3 .3 1"/>
      </material>
    </visual>
  </link>
  <link name="right_wheel_link">
    <collision>
      <geometry>
        <cylinder length="0.05" radius="0.0619125"/>
      </geometry>
    </collision>
    <visual>
      <geometry>
        <cylinder length="0.05" radius="0.0619125"/>
      </geometry>
      <material name="dark_grey">
        <color rgba=".3 .3 .3 1"/>
      </material>
    </visual>
  </link>
  <!-- Joints -->
  <joint name="base_caster" type="fixed">
    <parent link="base_link"/>
    <child link="caster"/>
    <origin xyz="-0.254 0 0.03175"/>
  </joint>
  <joint name="base_left_wheel" type="continuous">
    <parent link="base_link"/>
    <child link="left_wheel_link"/>
    <origin rpy="1.57079632679 0 0" xyz="0.2413 -0.2536 0.0619125"/>
    <axis xyz="0 1 0"/>
  </joint>
  <joint name="base_right_wheel" type="continuous">
    <parent link="base_link"/>
    <child link="right_wheel_link"/>
    <origin rpy="1.57079632679 0 0" xyz="0.2413 0.2536 0.0619125"/>
    <axis xyz="0 1 0"/>
  </joint>
</robot>
