<?xml version='1.0'?>
<sdf version='1.4'>
  <model name="Collection_bot">
    <static>false</static>

    <!-- //////////// -->
    <link name="base_link">
      <pose>0 0 0.1 0 0 0</pose>
      <collision name="collision">
        <geometry>
          <box>
            <size>0.6096 0.4572 0.1</size>
          </box>
        </geometry>
      </collision>
      <visual name="visual">
        <geometry>
          <box>
            <size>0.6096 0.4572 0.1</size>
          </box>
        </geometry>
        <material>
          <ambient>0.6 0.6 1 1</ambient>
          <diffuse>0.6 0.6 1 1</diffuse>
          <specular>0.1 0.1 0.1 1</specular>
          <emissive>0 0 0 0</emissive>
        </material>
      </visual>

      <collision name="caster_collision">
        <pose>-0.254 0 -0.06905 0 0 0</pose>
        <geometry>
          <sphere>
            <radius>0.03175</radius>
          </sphere>
        </geometry>
        <surface>
          <friction>
            <ode>
              <mu>0</mu>
              <mu2>0</mu2>
              <slip1>1.0</slip1>
              <slip2>1.0</slip2>
            </ode>
          </friction>
        </surface>
      </collision>
      <visual name="caster_visual">
        <pose>-0.254 0 -0.06905 0 0 0</pose>
        <geometry>
          <sphere>
            <radius>0.03175</radius>
          </sphere>
        </geometry>
        <material>
          <ambient>0.3 0.3 0.3 1</ambient>
          <diffuse>0.3 0.3 0.3 1</diffuse>
          <specular>0.1 0.1 0.1 1</specular>
          <emissive>0 0 0 0</emissive>
        </material>
      </visual>
    </link>
    
    <link name="left_wheel_link">
      <pose>0.2413 -0.2536 0.0619125 1.57079632679 0 0</pose>
      <collision name="collision">
        <geometry>
          <cylinder>
            <length>0.05</length>
            <radius>0.0619125</radius>
          </cylinder>
        </geometry>
      </collision>
      <visual name="visual">
        <geometry>
          <cylinder>
            <length>0.05</length>
            <radius>0.0619125</radius>
          </cylinder>
        </geometry>
        <material>
          <ambient>0.3 0.3 0.3 1</ambient>
          <diffuse>0.3 0.3 0.3 1</diffuse>
          <specular>0.1 0.1 0.1 1</specular>
          <emissive>0 0 0 0</emissive>
        </material>
      </visual>
    </link>

    <link name="right_wheel_link">
      <pose>0.2413 0.2536 0.0619125 1.57079632679 0 0</pose>
      <collision name="collision">
        <geometry>
          <cylinder>
            <length>0.05</length>
            <radius>0.0619125</radius>
          </cylinder>
        </geometry>
      </collision>
      <visual name="visual">
        <geometry>
          <cylinder>
            <length>0.05</length>
            <radius>0.0619125</radius>
          </cylinder>
        </geometry>
        <material>
          <ambient>0.3 0.3 0.3 1</ambient>
          <diffuse>0.3 0.3 0.3 1</diffuse>
          <specular>0.1 0.1 0.1 1</specular>
          <emissive>0 0 0 0</emissive>
        </material>
      </visual>
    </link>

    <!-- Joints -->
    <joint name="base_left_wheel" type="revolute">
      <parent>base_link</parent>
      <child>left_wheel_link</child>
      <axis>
        <xyz>0 1 0</xyz>
      </axis>
    </joint>

    <joint name="base_right_wheel" type="revolute">
      <parent>base_link</parent>
      <child>right_wheel_link</child>
      <axis>
        <xyz>0 1 0</xyz>
      </axis>
    </joint>
  </model>
</sdf>
